train_images (10000, 32, 32, 3)
train_labels (10000, 10)
test_images (10000, 32, 32, 3)
test_labels (10000, 10)
get_dataset_details return
Start working, dev= 7fe7
Traceback (most recent call last):
  File "D:\anaconda\envs\BlockchainForFederatedLearning\lib\site-packages\urllib3\connection.py", line 159, in _new_conn
    (self._dns_host, self.port), self.timeout, **extra_kw)
  File "D:\anaconda\envs\BlockchainForFederatedLearning\lib\site-packages\urllib3\util\connection.py", line 80, in create_connection
    raise err
  File "D:\anaconda\envs\BlockchainForFederatedLearning\lib\site-packages\urllib3\util\connection.py", line 70, in create_connection
    sock.connect(sa)
ConnectionRefusedError: [WinError 10061] 由于目标计算机积极拒绝，无法连接。

During handling of the above exception, another exception occurred:

Traceback (most recent call last):
  File "D:\anaconda\envs\BlockchainForFederatedLearning\lib\site-packages\urllib3\connectionpool.py", line 600, in urlopen
    chunked=chunked)
  File "D:\anaconda\envs\BlockchainForFederatedLearning\lib\site-packages\urllib3\connectionpool.py", line 354, in _make_request
    conn.request(method, url, **httplib_request_kw)
  File "D:\anaconda\envs\BlockchainForFederatedLearning\lib\http\client.py", line 1287, in request
    self._send_request(method, url, body, headers, encode_chunked)
  File "D:\anaconda\envs\BlockchainForFederatedLearning\lib\http\client.py", line 1333, in _send_request
    self.endheaders(body, encode_chunked=encode_chunked)
  File "D:\anaconda\envs\BlockchainForFederatedLearning\lib\http\client.py", line 1282, in endheaders
    self._send_output(message_body, encode_chunked=encode_chunked)
  File "D:\anaconda\envs\BlockchainForFederatedLearning\lib\http\client.py", line 1042, in _send_output
    self.send(msg)
  File "D:\anaconda\envs\BlockchainForFederatedLearning\lib\http\client.py", line 980, in send
    self.connect()
  File "D:\anaconda\envs\BlockchainForFederatedLearning\lib\site-packages\urllib3\connection.py", line 181, in connect
    conn = self._new_conn()
  File "D:\anaconda\envs\BlockchainForFederatedLearning\lib\site-packages\urllib3\connection.py", line 168, in _new_conn
    self, "Failed to establish a new connection: %s" % e)
urllib3.exceptions.NewConnectionError: <urllib3.connection.HTTPConnection object at 0x000001E601B88CF8>: Failed to establish a new connection: [WinError 10061] 由于目标计算机积极拒绝，无法连接。

During handling of the above exception, another exception occurred:

Traceback (most recent call last):
  File "D:\anaconda\envs\BlockchainForFederatedLearning\lib\site-packages\requests\adapters.py", line 449, in send
    timeout=timeout
  File "D:\anaconda\envs\BlockchainForFederatedLearning\lib\site-packages\urllib3\connectionpool.py", line 638, in urlopen
    _stacktrace=sys.exc_info()[2])
  File "D:\anaconda\envs\BlockchainForFederatedLearning\lib\site-packages\urllib3\util\retry.py", line 398, in increment
    raise MaxRetryError(_pool, url, error or ResponseError(cause))
urllib3.exceptions.MaxRetryError: HTTPConnectionPool(host='127.0.0.1', port=5000): Max retries exceeded with url: /status (Caused by NewConnectionError('<urllib3.connection.HTTPConnection object at 0x000001E601B88CF8>: Failed to establish a new connection: [WinError 10061] 由于目标计算机积极拒绝，无法连接。',))

During handling of the above exception, another exception occurred:

Traceback (most recent call last):
  File "client.py", line 129, in <module>
    c.work(device_id, args.global_rounds, args.local_epochs)
  File "client.py", line 87, in work
    status = self.get_miner_status()
  File "client.py", line 37, in get_miner_status
    r = requests.get(f'http://{self.miner}/status')
  File "D:\anaconda\envs\BlockchainForFederatedLearning\lib\site-packages\requests\api.py", line 75, in get
    return request('get', url, params=params, **kwargs)
  File "D:\anaconda\envs\BlockchainForFederatedLearning\lib\site-packages\requests\api.py", line 60, in request
    return session.request(method=method, url=url, **kwargs)
  File "D:\anaconda\envs\BlockchainForFederatedLearning\lib\site-packages\requests\sessions.py", line 524, in request
    resp = self.send(prep, **send_kwargs)
  File "D:\anaconda\envs\BlockchainForFederatedLearning\lib\site-packages\requests\sessions.py", line 637, in send
    r = adapter.send(request, **kwargs)
  File "D:\anaconda\envs\BlockchainForFederatedLearning\lib\site-packages\requests\adapters.py", line 516, in send
    raise ConnectionError(e, request=request)
requests.exceptions.ConnectionError: HTTPConnectionPool(host='127.0.0.1', port=5000): Max retries exceeded with url: /status (Caused by NewConnectionError('<urllib3.connection.HTTPConnection object at 0x000001E601B88CF8>: Failed to establish a new connection: [WinError 10061] 由于目标计算机积极拒绝，无法连接。',))
